Workbook

Sheet &UnStack

Sheet &DataIndices

Sheet &DataCopy

Sheet &GraphData

Sheet &WorkArea

Sheet &Miscel_Area

Sheet Data
A1: Customer | B1: Type of Customer | C1: Items | D1: Net Sales | E1: Method of Payment | F1: Gender | G1: Marital Status | H1: Age
A2: 1 | B2: Regular | C2: 1 | D2: 39.5 | E2: Discover | F2: Male | G2: Married | H2: 32
A3: 2 | B3: Promotional | C3: 1 | D3: 102.4 | E3: Proprietary Card | F3: Female | G3: Married | H3: 36
A4: 3 | B4: Regular | C4: 1 | D4: 22.5 | E4: Proprietary Card | F4: Female | G4: Married | H4: 32
A5: 4 | B5: Promotional | C5: 5 | D5: 100.4 | E5: Proprietary Card | F5: Female | G5: Married | H5: 28
A6: 5 | B6: Regular | C6: 2 | D6: 54 | E6: MasterCard | F6: Female | G6: Married | H6: 34
A7: 6 | B7: Regular | C7: 1 | D7: 44.5 | E7: MasterCard | F7: Female | G7: Married | H7: 44
A8: 7 | B8: Promotional | C8: 2 | D8: 78 | E8: Proprietary Card | F8: Female | G8: Married | H8: 30
A9: 8 | B9: Regular | C9: 1 | D9: 22.5 | E9: Visa | F9: Female | G9: Married | H9: 40
A10: 9 | B10: Promotional | C10: 2 | D10: 56.52 | E10: Proprietary Card | F10: Female | G10: Married | H10: 46
A11: 10 | B11: Regular | C11: 1 | D11: 44.5 | E11: Proprietary Card | F11: Female | G11: Married | H11: 36
A12: 11 | B12: Regular | C12: 1 | D12: 29.5 | E12: Proprietary Card | F12: Female | G12: Married | H12: 48
A13: 12 | B13: Promotional | C13: 1 | D13: 31.6 | E13: Proprietary Card | F13: Female | G13: Married | H13: 40
... A101: 100 | B101: Promotional | C101: 1 | D101: 28.44 | E101: Proprietary Card | F101: Female | G101: Married | H101: 44

Sheet 01 Location Measures
A1: Week 3: Measures of Location
A3: Measure | B3: Net Sales ($)
A4: Mean | B4: =AVERAGE(Data!$D$2:$D$101) -> 77.6005
A5: Median | B5: =MEDIAN(Data!$D$2:$D$101) -> 59.705
A6: Mode | B6: =_xlfn.MODE.SNGL(Data!$D$2:$D$101) -> 31.6
A7: First quartile, Q1 | B7: =_xlfn.PERCENTILE.EXC(Data!$D$2:$D$101,0.25) -> 39.6
A8: Third quartile, Q3 | B8: =_xlfn.PERCENTILE.EXC(Data!$D$2:$D$101,0.75) -> 101.9
A9: 90th percentile, P90 | B9: =_xlfn.PERCENTILE.EXC(Data!$D$2:$D$101,0.9) -> 154.468
A17: How to recreate this output in Excel
A18: 1. Use the Net Sales values in Data!D2:D101.
A19: 2. Calculate the mean with =AVERAGE(Data!D2:D101), the median with =MEDIAN(Data!D2:D101), and the mode with =MODE.SNGL(Data!D2:D101).
A20: 3. For a percentile, sort Net Sales from smallest to largest and calculate its location with Lp=(p/100)*(n+1).
A21: 4. If Lp is not a whole number, interpolate between the observations immediately below and above that location.
A22: 5. In Excel, enter =PERCENTILE.EXC(Data!D2:D101,0.25) for Q1. Use 0.75 for Q3 and 0.90 for P90. These formulas use the location rule above.

Sheet 02 Variability
A1: Week 3: Measures of Variability
A3: Variable | B3: Mean | C3: Range | D3: IQR | E3: Sample variance | F3: Sample standard deviation | G3: Population standard deviation | H3: CV (%)
A4: Net Sales ($) | B4: =AVERAGE(Data!$D$2:$D$101) -> 77.6005 | C4: =MAX(Data!$D$2:$D$101)-MIN(Data!$D$2:$D$101) -> 274.36 | D4: =_xlfn.PERCENTILE.EXC(Data!$D$2:$D$101,0.75)-_xlfn.PERCENTILE.EXC(Data!$D$2:$D$101,0.25) -> 62.3 | E4: =_xlfn.VAR.S(Data!$D$2:$D$101) -> 3098.5854 | F4: =_xlfn.STDEV.S(Data!$D$2:$D$101) -> 55.664938 | G4: =_xlfn.STDEV.P(Data!$D$2:$D$101) -> 55.385914 | H4: =F4/B4*100 -> 71.732706
A5: Age (years) | B5: =AVERAGE(Data!$H$2:$H$101) -> 43.08 | C5: =MAX(Data!$H$2:$H$101)-MIN(Data!$H$2:$H$101) -> 58 | D5: =_xlfn.PERCENTILE.EXC(Data!$H$2:$H$101,0.75)-_xlfn.PERCENTILE.EXC(Data!$H$2:$H$101,0.25) -> 18 | E5: =_xlfn.VAR.S(Data!$H$2:$H$101) -> 153.48848 | F5: =_xlfn.STDEV.S(Data!$H$2:$H$101) -> 12.389047 | G5: =_xlfn.STDEV.P(Data!$H$2:$H$101) -> 12.326946 | H5: =F5/B5*100 -> 28.758233
A8: How to recreate this output in Excel
A9: 1. Use Net Sales in Data!D2:D101 and Age in Data!H2:H101.
A10: 2. Calculate the range with =MAX(range)-MIN(range).
A11: 3. For Net Sales, enter =PERCENTILE.EXC(Data!D2:D101,0.75)-PERCENTILE.EXC(Data!D2:D101,0.25) for IQR. Use H2:H101 for Age.
A12: 4. Use =VAR.S(range) and =STDEV.S(range) for sample variance and sample standard deviation.
A13: 5. Use =STDEV.P(range) only when treating all observations as the complete population.
A14: 6. Calculate the coefficient of variation with =STDEV.S(range)/AVERAGE(range)*100. Compare CV only for variables with a meaningful zero.

Sheet 03 Shape Measures
A1: Week 3: Skewness and Kurtosis
A3: Measure | B3: Direct moment calculation | C3: Adjusted sample calculation
A4: Skewness | B4: =SUMPRODUCT((Data!$D$2:$D$101-AVERAGE(Data!$D$2:$D$101))^3)/COUNT(Data!$D$2:$D$101)/(_xlfn.VAR.P(Data!$D$2:$D$101)^1.5) -> 1.6891632 | C4: =SKEW(Data!$D$2:$D$101) -> 1.7149961
A5: Pearson kurtosis | B5: =SUMPRODUCT((Data!$D$2:$D$101-AVERAGE(Data!$D$2:$D$101))^4)/COUNT(Data!$D$2:$D$101)/(_xlfn.VAR.P(Data!$D$2:$D$101)^2) -> 5.9352408 | C5: =C6+3 -> 6.149955
A6: Excess kurtosis | B6: =B5-3 -> 2.9352408 | C6: =KURT(Data!$D$2:$D$101) -> 3.149955
A9: Interpretation | B9: Net Sales is positively skewed and has heavier tails than a normal distribution.
A12: How to recreate this output in Excel
A13: 1. Copy Net Sales from Data!D2:D101 into one column and calculate the mean.
A14: 2. Create helper columns for deviation from the mean, deviation squared, deviation cubed, and deviation to the fourth power.
A15: 3. For direct skewness, divide the average cubed deviation by the average squared deviation raised to 1.5.
A16: 4. For direct Pearson kurtosis, divide the average fourth-power deviation by the square of the average squared deviation. Subtract 3 for excess kurtosis.
A17: 5. Use =SKEW(Data!D2:D101) for adjusted sample skewness and =KURT(Data!D2:D101) for adjusted sample excess kurtosis. Add 3 to obtain adjusted Pearson kurtosis.

Sheet 04 Z Scores and Outliers
A1: Week 3: Standard Scores and Outlier Checks
A3: Mean | B3: =AVERAGE(Data!$D$2:$D$101) -> 77.6005
A4: Sample standard deviation | B4: =_xlfn.STDEV.S(Data!$D$2:$D$101) -> 55.664938
A5: Q1 | B5: =_xlfn.PERCENTILE.EXC(Data!$D$2:$D$101,0.25) -> 39.6
A6: Q3 | B6: =_xlfn.PERCENTILE.EXC(Data!$D$2:$D$101,0.75) -> 101.9
A7: IQR | B7: =B6-B5 -> 62.3
A8: Lower fence | B8: =B5-1.5*B7 -> -53.85
A9: Upper fence | B9: =B6+1.5*B7 -> 195.35
A10: IQR flags | B10: =COUNTIF(D15:D114,"Flag") -> 5
A11: |z| > 3 flags | B11: =COUNTIF(E15:E114,"Flag") -> 3
A14: Customer | B14: Net Sales ($) | C14: z-score | D14: IQR rule | E14: |z| > 3 rule
A15: =Data!A2 -> 1 | B15: =Data!D2 -> 39.5 | C15: =(B15-$B$3)/$B$4 -> -0.68446137 | D15: =IF(OR(B15<$B$8,B15>$B$9),"Flag","") | E15: =IF(ABS(C15)>3,"Flag","")
A16: =Data!A3 -> 2 | B16: =Data!D3 -> 102.4 | C16: =(B16-$B$3)/$B$4 -> 0.44551383 | D16: =IF(OR(B16<$B$8,B16>$B$9),"Flag","") | E16: =IF(ABS(C16)>3,"Flag","")
A17: =Data!A4 -> 3 | B17: =Data!D4 -> 22.5 | C17: =(B17-$B$3)/$B$4 -> -0.98986007 | D17: =IF(OR(B17<$B$8,B17>$B$9),"Flag","") | E17: =IF(ABS(C17)>3,"Flag","")
A18: =Data!A5 -> 4 | B18: =Data!D5 -> 100.4 | C18: =(B18-$B$3)/$B$4 -> 0.40958457 | D18: =IF(OR(B18<$B$8,B18>$B$9),"Flag","") | E18: =IF(ABS(C18)>3,"Flag","")
A19: =Data!A6 -> 5 | B19: =Data!D6 -> 54 | C19: =(B19-$B$3)/$B$4 -> -0.42397424 | D19: =IF(OR(B19<$B$8,B19>$B$9),"Flag","") | E19: =IF(ABS(C19)>3,"Flag","")
A20: =Data!A7 -> 6 | B20: =Data!D7 -> 44.5 | C20: =(B20-$B$3)/$B$4 -> -0.59463822 | D20: =IF(OR(B20<$B$8,B20>$B$9),"Flag","") | E20: =IF(ABS(C20)>3,"Flag","")
A21: =Data!A8 -> 7 | B21: =Data!D8 -> 78 | C21: =(B21-$B$3)/$B$4 -> 0.0071768695 | D21: =IF(OR(B21<$B$8,B21>$B$9),"Flag","") | E21: =IF(ABS(C21)>3,"Flag","")
A22: =Data!A9 -> 8 | B22: =Data!D9 -> 22.5 | C22: =(B22-$B$3)/$B$4 -> -0.98986007 | D22: =IF(OR(B22<$B$8,B22>$B$9),"Flag","") | E22: =IF(ABS(C22)>3,"Flag","")
A23: =Data!A10 -> 9 | B23: =Data!D10 -> 56.52 | C23: =(B23-$B$3)/$B$4 -> -0.37870337 | D23: =IF(OR(B23<$B$8,B23>$B$9),"Flag","") | E23: =IF(ABS(C23)>3,"Flag","")
A24: =Data!A11 -> 10 | B24: =Data!D11 -> 44.5 | C24: =(B24-$B$3)/$B$4 -> -0.59463822 | D24: =IF(OR(B24<$B$8,B24>$B$9),"Flag","") | E24: =IF(ABS(C24)>3,"Flag","")
A25: =Data!A12 -> 11 | B25: =Data!D12 -> 29.5 | C25: =(B25-$B$3)/$B$4 -> -0.86410767 | D25: =IF(OR(B25<$B$8,B25>$B$9),"Flag","") | E25: =IF(ABS(C25)>3,"Flag","")
A26: =Data!A13 -> 12 | B26: =Data!D13 -> 31.6 | C26: =(B26-$B$3)/$B$4 -> -0.82638194 | D26: =IF(OR(B26<$B$8,B26>$B$9),"Flag","") | E26: =IF(ABS(C26)>3,"Flag","")
... A114: =Data!A101 -> 100 | B114: =Data!D101 -> 28.44 | C114: =(B114-$B$3)/$B$4 -> -0.88315017 | D114: =IF(OR(B114<$B$8,B114>$B$9),"Flag","") | E114: =IF(ABS(C114)>3,"Flag","")
A117: How to recreate this output in Excel
A118: 1. Copy Customer and Net Sales from the Data sheet.
A119: 2. Calculate the mean and sample standard deviation with =AVERAGE(Data!D2:D101) and =STDEV.S(Data!D2:D101).
A120: 3. For the first customer, calculate z with =(B15-$B$3)/$B$4 and fill the formula down.
A121: 4. Calculate Q1, Q3, and IQR, then calculate the fences as Q1-1.5*IQR and Q3+1.5*IQR.
A122: 5. Use =IF(OR(B15<$B$8,B15>$B$9),"Flag","") for the IQR rule and fill down.
A123: 6. Use =IF(ABS(C15)>3,"Flag","") for the z-score rule and fill down. Investigate flagged observations before deciding how to handle them.

Sheet 05 Five Number Summary
A1: Week 3: Five-Number Summary
A3: Minimum | B3: Q1 | C3: Median | D3: Q3 | E3: Maximum
A4: =MIN(Data!$D$2:$D$101) -> 13.23 | B4: =_xlfn.PERCENTILE.EXC(Data!$D$2:$D$101,0.25) -> 39.6 | C4: =MEDIAN(Data!$D$2:$D$101) -> 59.705 | D4: =_xlfn.PERCENTILE.EXC(Data!$D$2:$D$101,0.75) -> 101.9 | E4: =MAX(Data!$D$2:$D$101) -> 287.59
A7: IQR | B7: =D4-B4 -> 62.3
A10: How to recreate this output in Excel
A11: 1. Use the Net Sales values in Data!D2:D101.
A12: 2. Use =MIN(range) and =MAX(range) for the endpoints and =MEDIAN(range) for the center.
A13: 3. Calculate Q1 and Q3 with the Week 3 percentile location formula.
A14: 4. Calculate IQR as Q3-Q1. Read the five values together before interpreting spread or possible outliers.

Sheet 06 Box Plots by Type
A1: Week 3: Net Sales by Customer Type
A3: Customer type | B3: N | C3: Q1 | D3: Median | E3: Q3 | F3: IQR outliers | J3: Lower fence | K3: Upper fence | L3: Lower endpoint | M3: Upper endpoint
A4: Regular | B4: =COUNT(A10:A109) -> 30 | C4: =_xlfn.PERCENTILE.EXC(A10:A109,0.25) -> 39.375 | D4: =MEDIAN(A10:A109) -> 51 | E4: =_xlfn.PERCENTILE.EXC(A10:A109,0.75) -> 74.25 | F4: =COUNTIF(A10:A109,"<"&J4)+COUNTIF(A10:A109,">"&K4) -> 2 | J4: =C4-1.5*(E4-C4) -> -12.9375 | K4: =E4+1.5*(E4-C4) -> 126.5625 | L4: =_xlfn.AGGREGATE(15,6,A10:A109/(ISNUMBER(A10:A109))/(A10:A109>=J4)/(A10:A109<=K4),1) -> 22.5 | M4: =_xlfn.AGGREGATE(14,6,A10:A109/(ISNUMBER(A10:A109))/(A10:A109>=J4)/(A10:A109<=K4),1) -> 123.5
A5: Promotional | B5: =COUNT(B10:B109) -> 70 | C5: =_xlfn.PERCENTILE.EXC(B10:B109,0.25) -> 43.5 | D5: =MEDIAN(B10:B109) -> 63.42 | E5: =_xlfn.PERCENTILE.EXC(B10:B109,0.75) -> 109.385 | F5: =COUNTIF(B10:B109,"<"&J5)+COUNTIF(B10:B109,">"&K5) -> 4 | J5: =C5-1.5*(E5-C5) -> -55.3275 | K5: =E5+1.5*(E5-C5) -> 208.2125 | L5: =_xlfn.AGGREGATE(15,6,B10:B109/(ISNUMBER(B10:B109))/(B10:B109>=J5)/(B10:B109<=K5),1) -> 13.23 | M5: =_xlfn.AGGREGATE(14,6,B10:B109/(ISNUMBER(B10:B109))/(B10:B109>=J5)/(B10:B109<=K5),1) -> 198.8
A9: Regular | B9: Promotional | J9: Regular: sales | K9: Regular: position | L9: Promotional: sales | M9: Promotional: position
A10: =IFERROR(INDEX(Data!$D$2:$D$101,_xlfn.AGGREGATE(15,6,(ROW(Data!$B$2:$B$101)-ROW(Data!$B$2)+1)/(Data!$B$2:$B$101=A$9),ROWS(A$10:A10))),"") -> 39.5 | B10: =IFERROR(INDEX(Data!$D$2:$D$101,_xlfn.AGGREGATE(15,6,(ROW(Data!$B$2:$B$101)-ROW(Data!$B$2)+1)/(Data!$B$2:$B$101=B$9),ROWS(B$10:B10))),"") -> 102.4 | J10: =$L$4 -> 22.5 | K10: 0.9 | L10: =$L$5 -> 13.23 | M10: 1.9
A11: =IFERROR(INDEX(Data!$D$2:$D$101,_xlfn.AGGREGATE(15,6,(ROW(Data!$B$2:$B$101)-ROW(Data!$B$2)+1)/(Data!$B$2:$B$101=A$9),ROWS(A$10:A11))),"") -> 22.5 | B11: =IFERROR(INDEX(Data!$D$2:$D$101,_xlfn.AGGREGATE(15,6,(ROW(Data!$B$2:$B$101)-ROW(Data!$B$2)+1)/(Data!$B$2:$B$101=B$9),ROWS(B$10:B11))),"") -> 100.4 | J11: =$L$4 -> 22.5 | K11: 1.1 | L11: =$L$5 -> 13.23 | M11: 2.1
A12: =IFERROR(INDEX(Data!$D$2:$D$101,_xlfn.AGGREGATE(15,6,(ROW(Data!$B$2:$B$101)-ROW(Data!$B$2)+1)/(Data!$B$2:$B$101=A$9),ROWS(A$10:A12))),"") -> 54 | B12: =IFERROR(INDEX(Data!$D$2:$D$101,_xlfn.AGGREGATE(15,6,(ROW(Data!$B$2:$B$101)-ROW(Data!$B$2)+1)/(Data!$B$2:$B$101=B$9),ROWS(B$10:B12))),"") -> 78 | J12: =$L$4 -> 22.5 | K12: 1 | L12: =$L$5 -> 13.23 | M12: 2
A13: =IFERROR(INDEX(Data!$D$2:$D$101,_xlfn.AGGREGATE(15,6,(ROW(Data!$B$2:$B$101)-ROW(Data!$B$2)+1)/(Data!$B$2:$B$101=A$9),ROWS(A$10:A13))),"") -> 44.5 | B13: =IFERROR(INDEX(Data!$D$2:$D$101,_xlfn.AGGREGATE(15,6,(ROW(Data!$B$2:$B$101)-ROW(Data!$B$2)+1)/(Data!$B$2:$B$101=B$9),ROWS(B$10:B13))),"") -> 56.52 | J13: =$C$4 -> 39.375 | K13: 1 | L13: =$C$5 -> 43.5 | M13: 2
A14: =IFERROR(INDEX(Data!$D$2:$D$101,_xlfn.AGGREGATE(15,6,(ROW(Data!$B$2:$B$101)-ROW(Data!$B$2)+1)/(Data!$B$2:$B$101=A$9),ROWS(A$10:A14))),"") -> 22.5 | B14: =IFERROR(INDEX(Data!$D$2:$D$101,_xlfn.AGGREGATE(15,6,(ROW(Data!$B$2:$B$101)-ROW(Data!$B$2)+1)/(Data!$B$2:$B$101=B$9),ROWS(B$10:B14))),"") -> 31.6 | J14: =$C$4 -> 39.375 | K14: 0.8 | L14: =$C$5 -> 43.5 | M14: 1.8
A15: =IFERROR(INDEX(Data!$D$2:$D$101,_xlfn.AGGREGATE(15,6,(ROW(Data!$B$2:$B$101)-ROW(Data!$B$2)+1)/(Data!$B$2:$B$101=A$9),ROWS(A$10:A15))),"") -> 44.5 | B15: =IFERROR(INDEX(Data!$D$2:$D$101,_xlfn.AGGREGATE(15,6,(ROW(Data!$B$2:$B$101)-ROW(Data!$B$2)+1)/(Data!$B$2:$B$101=B$9),ROWS(B$10:B15))),"") -> 160.4 | J15: =$E$4 -> 74.25 | K15: 0.8 | L15: =$E$5 -> 109.385 | M15: 1.8
A16: =IFERROR(INDEX(Data!$D$2:$D$101,_xlfn.AGGREGATE(15,6,(ROW(Data!$B$2:$B$101)-ROW(Data!$B$2)+1)/(Data!$B$2:$B$101=A$9),ROWS(A$10:A16))),"") -> 29.5 | B16: =IFERROR(INDEX(Data!$D$2:$D$101,_xlfn.AGGREGATE(15,6,(ROW(Data!$B$2:$B$101)-ROW(Data!$B$2)+1)/(Data!$B$2:$B$101=B$9),ROWS(B$10:B16))),"") -> 64.5 | J16: =$E$4 -> 74.25 | K16: 1 | L16: =$E$5 -> 109.385 | M16: 2
A17: =IFERROR(INDEX(Data!$D$2:$D$101,_xlfn.AGGREGATE(15,6,(ROW(Data!$B$2:$B$101)-ROW(Data!$B$2)+1)/(Data!$B$2:$B$101=A$9),ROWS(A$10:A17))),"") -> 49.5 | B17: =IFERROR(INDEX(Data!$D$2:$D$101,_xlfn.AGGREGATE(15,6,(ROW(Data!$B$2:$B$101)-ROW(Data!$B$2)+1)/(Data!$B$2:$B$101=B$9),ROWS(B$10:B17))),"") -> 71.4 | J17: =$M$4 -> 123.5 | K17: 1 | L17: =$M$5 -> 198.8 | M17: 2
A18: =IFERROR(INDEX(Data!$D$2:$D$101,_xlfn.AGGREGATE(15,6,(ROW(Data!$B$2:$B$101)-ROW(Data!$B$2)+1)/(Data!$B$2:$B$101=A$9),ROWS(A$10:A18))),"") -> 54.5 | B18: =IFERROR(INDEX(Data!$D$2:$D$101,_xlfn.AGGREGATE(15,6,(ROW(Data!$B$2:$B$101)-ROW(Data!$B$2)+1)/(Data!$B$2:$B$101=B$9),ROWS(B$10:B18))),"") -> 94 | J18: =$M$4 -> 123.5 | K18: 0.9 | L18: =$M$5 -> 198.8 | M18: 1.9
A19: =IFERROR(INDEX(Data!$D$2:$D$101,_xlfn.AGGREGATE(15,6,(ROW(Data!$B$2:$B$101)-ROW(Data!$B$2)+1)/(Data!$B$2:$B$101=A$9),ROWS(A$10:A19))),"") -> 74 | B19: =IFERROR(INDEX(Data!$D$2:$D$101,_xlfn.AGGREGATE(15,6,(ROW(Data!$B$2:$B$101)-ROW(Data!$B$2)+1)/(Data!$B$2:$B$101=B$9),ROWS(B$10:B19))),"") -> 38.5 | J19: =$M$4 -> 123.5 | K19: 1.1 | L19: =$M$5 -> 198.8 | M19: 2.1
A20: =IFERROR(INDEX(Data!$D$2:$D$101,_xlfn.AGGREGATE(15,6,(ROW(Data!$B$2:$B$101)-ROW(Data!$B$2)+1)/(Data!$B$2:$B$101=A$9),ROWS(A$10:A20))),"") -> 44.5 | B20: =IFERROR(INDEX(Data!$D$2:$D$101,_xlfn.AGGREGATE(15,6,(ROW(Data!$B$2:$B$101)-ROW(Data!$B$2)+1)/(Data!$B$2:$B$101=B$9),ROWS(B$10:B20))),"") -> 44.8 | J20: =$M$4 -> 123.5 | K20: 1 | L20: =$M$5 -> 198.8 | M20: 2
A21: =IFERROR(INDEX(Data!$D$2:$D$101,_xlfn.AGGREGATE(15,6,(ROW(Data!$B$2:$B$101)-ROW(Data!$B$2)+1)/(Data!$B$2:$B$101=A$9),ROWS(A$10:A21))),"") -> 75 | B21: =IFERROR(INDEX(Data!$D$2:$D$101,_xlfn.AGGREGATE(15,6,(ROW(Data!$B$2:$B$101)-ROW(Data!$B$2)+1)/(Data!$B$2:$B$101=B$9),ROWS(B$10:B21))),"") -> 31.6 | J21: =$E$4 -> 74.25 | K21: 1 | L21: =$E$5 -> 109.385 | M21: 2
A22: =IFERROR(INDEX(Data!$D$2:$D$101,_xlfn.AGGREGATE(15,6,(ROW(Data!$B$2:$B$101)-ROW(Data!$B$2)+1)/(Data!$B$2:$B$101=A$9),ROWS(A$10:A22))),"") -> 40 | B22: =IFERROR(INDEX(Data!$D$2:$D$101,_xlfn.AGGREGATE(15,6,(ROW(Data!$B$2:$B$101)-ROW(Data!$B$2)+1)/(Data!$B$2:$B$101=B$9),ROWS(B$10:B22))),"") -> 70.82 | J22: =$E$4 -> 74.25 | K22: 1.2 | L22: =$E$5 -> 109.385 | M22: 2.2
A23: =IFERROR(INDEX(Data!$D$2:$D$101,_xlfn.AGGREGATE(15,6,(ROW(Data!$B$2:$B$101)-ROW(Data!$B$2)+1)/(Data!$B$2:$B$101=A$9),ROWS(A$10:A23))),"") -> 29.5 | B23: =IFERROR(INDEX(Data!$D$2:$D$101,_xlfn.AGGREGATE(15,6,(ROW(Data!$B$2:$B$101)-ROW(Data!$B$2)+1)/(Data!$B$2:$B$101=B$9),ROWS(B$10:B23))),"") -> 266 | J23: =$C$4 -> 39.375 | K23: 1.2 | L23: =$C$5 -> 43.5 | M23: 2.2
A24: =IFERROR(INDEX(Data!$D$2:$D$101,_xlfn.AGGREGATE(15,6,(ROW(Data!$B$2:$B$101)-ROW(Data!$B$2)+1)/(Data!$B$2:$B$101=A$9),ROWS(A$10:A24))),"") -> 102.5 | B24: =IFERROR(INDEX(Data!$D$2:$D$101,_xlfn.AGGREGATE(15,6,(ROW(Data!$B$2:$B$101)-ROW(Data!$B$2)+1)/(Data!$B$2:$B$101=B$9),ROWS(B$10:B24))),"") -> 39.5 | J24: =$C$4 -> 39.375 | K24: 0.8 | L24: =$C$5 -> 43.5 | M24: 1.8
A25: =IFERROR(INDEX(Data!$D$2:$D$101,_xlfn.AGGREGATE(15,6,(ROW(Data!$B$2:$B$101)-ROW(Data!$B$2)+1)/(Data!$B$2:$B$101=A$9),ROWS(A$10:A25))),"") -> 52.5 | B25: =IFERROR(INDEX(Data!$D$2:$D$101,_xlfn.AGGREGATE(15,6,(ROW(Data!$B$2:$B$101)-ROW(Data!$B$2)+1)/(Data!$B$2:$B$101=B$9),ROWS(B$10:B25))),"") -> 30.02 | J25: =$D$4 -> 51 | K25: 0.8 | L25: =$D$5 -> 63.42 | M25: 1.8
A26: =IFERROR(INDEX(Data!$D$2:$D$101,_xlfn.AGGREGATE(15,6,(ROW(Data!$B$2:$B$101)-ROW(Data!$B$2)+1)/(Data!$B$2:$B$101=A$9),ROWS(A$10:A26))),"") -> 123.5 | B26: =IFERROR(INDEX(Data!$D$2:$D$101,_xlfn.AGGREGATE(15,6,(ROW(Data!$B$2:$B$101)-ROW(Data!$B$2)+1)/(Data!$B$2:$B$101=B$9),ROWS(B$10:B26))),"") -> 192.8 | J26: =$D$4 -> 51 | K26: 1.2 | L26: =$D$5 -> 63.42 | M26: 2.2
A27: =IFERROR(INDEX(Data!$D$2:$D$101,_xlfn.AGGREGATE(15,6,(ROW(Data!$B$2:$B$101)-ROW(Data!$B$2)+1)/(Data!$B$2:$B$101=A$9),ROWS(A$10:A27))),"") -> 25 | B27: =IFERROR(INDEX(Data!$D$2:$D$101,_xlfn.AGGREGATE(15,6,(ROW(Data!$B$2:$B$101)-ROW(Data!$B$2)+1)/(Data!$B$2:$B$101=B$9),ROWS(B$10:B27))),"") -> 71.2 | J27: =$D$4 -> 51 | K27: 1.2 | L27: =$D$5 -> 63.42 | M27: 2.2
A28: =IFERROR(INDEX(Data!$D$2:$D$101,_xlfn.AGGREGATE(15,6,(ROW(Data!$B$2:$B$101)-ROW(Data!$B$2)+1)/(Data!$B$2:$B$101=A$9),ROWS(A$10:A28))),"") -> 58 | B28: =IFERROR(INDEX(Data!$D$2:$D$101,_xlfn.AGGREGATE(15,6,(ROW(Data!$B$2:$B$101)-ROW(Data!$B$2)+1)/(Data!$B$2:$B$101=B$9),ROWS(B$10:B28))),"") -> 18 | J28: =$D$4 -> 51 | K28: 1.2 | L28: =$D$5 -> 63.42 | M28: 2.2
A29: =IFERROR(INDEX(Data!$D$2:$D$101,_xlfn.AGGREGATE(15,6,(ROW(Data!$B$2:$B$101)-ROW(Data!$B$2)+1)/(Data!$B$2:$B$101=A$9),ROWS(A$10:A29))),"") -> 74 | B29: =IFERROR(INDEX(Data!$D$2:$D$101,_xlfn.AGGREGATE(15,6,(ROW(Data!$B$2:$B$101)-ROW(Data!$B$2)+1)/(Data!$B$2:$B$101=B$9),ROWS(B$10:B29))),"") -> 63.2 | J29: =$D$4 -> 51 | K29: 1.2 | L29: =$D$5 -> 63.42 | M29: 2.2
A30: =IFERROR(INDEX(Data!$D$2:$D$101,_xlfn.AGGREGATE(15,6,(ROW(Data!$B$2:$B$101)-ROW(Data!$B$2)+1)/(Data!$B$2:$B$101=A$9),ROWS(A$10:A30))),"") -> 49.5 | B30: =IFERROR(INDEX(Data!$D$2:$D$101,_xlfn.AGGREGATE(15,6,(ROW(Data!$B$2:$B$101)-ROW(Data!$B$2)+1)/(Data!$B$2:$B$101=B$9),ROWS(B$10:B30))),"") -> 63.2
A31: =IFERROR(INDEX(Data!$D$2:$D$101,_xlfn.AGGREGATE(15,6,(ROW(Data!$B$2:$B$101)-ROW(Data!$B$2)+1)/(Data!$B$2:$B$101=A$9),ROWS(A$10:A31))),"") -> 69 | B31: =IFERROR(INDEX(Data!$D$2:$D$101,_xlfn.AGGREGATE(15,6,(ROW(Data!$B$2:$B$101)-ROW(Data!$B$2)+1)/(Data!$B$2:$B$101=B$9),ROWS(B$10:B31))),"") -> 105.5
A32: =IFERROR(INDEX(Data!$D$2:$D$101,_xlfn.AGGREGATE(15,6,(ROW(Data!$B$2:$B$101)-ROW(Data!$B$2)+1)/(Data!$B$2:$B$101=A$9),ROWS(A$10:A32))),"") -> 39 | B32: =IFERROR(INDEX(Data!$D$2:$D$101,_xlfn.AGGREGATE(15,6,(ROW(Data!$B$2:$B$101)-ROW(Data!$B$2)+1)/(Data!$B$2:$B$101=B$9),ROWS(B$10:B32))),"") -> 117.5 | J32: Regular: sales (outliers) | K32: Regular: position (outliers) | L32: Promotional: sales (outliers) | M32: Promotional: position (outliers)
A33: =IFERROR(INDEX(Data!$D$2:$D$101,_xlfn.AGGREGATE(15,6,(ROW(Data!$B$2:$B$101)-ROW(Data!$B$2)+1)/(Data!$B$2:$B$101=A$9),ROWS(A$10:A33))),"") -> 89 | B33: =IFERROR(INDEX(Data!$D$2:$D$101,_xlfn.AGGREGATE(15,6,(ROW(Data!$B$2:$B$101)-ROW(Data!$B$2)+1)/(Data!$B$2:$B$101=B$9),ROWS(B$10:B33))),"") -> 13.23 | J33: =IF(AND(ISNUMBER(A10),OR(A10<$J$4,A10>$K$4)),A10,NA()) -> #N/A | K33: 1 | L33: =IF(AND(ISNUMBER(B10),OR(B10<$J$5,B10>$K$5)),B10,NA()) -> #N/A | M33: 2
A34: =IFERROR(INDEX(Data!$D$2:$D$101,_xlfn.AGGREGATE(15,6,(ROW(Data!$B$2:$B$101)-ROW(Data!$B$2)+1)/(Data!$B$2:$B$101=A$9),ROWS(A$10:A34))),"") -> 37.5 | B34: =IFERROR(INDEX(Data!$D$2:$D$101,_xlfn.AGGREGATE(15,6,(ROW(Data!$B$2:$B$101)-ROW(Data!$B$2)+1)/(Data!$B$2:$B$101=B$9),ROWS(B$10:B34))),"") -> 198.8 | J34: =IF(AND(ISNUMBER(A11),OR(A11<$J$4,A11>$K$4)),A11,NA()) -> #N/A | K34: 1 | L34: =IF(AND(ISNUMBER(B11),OR(B11<$J$5,B11>$K$5)),B11,NA()) -> #N/A | M34: 2
A35: =IFERROR(INDEX(Data!$D$2:$D$101,_xlfn.AGGREGATE(15,6,(ROW(Data!$B$2:$B$101)-ROW(Data!$B$2)+1)/(Data!$B$2:$B$101=A$9),ROWS(A$10:A35))),"") -> 144 | B35: =IFERROR(INDEX(Data!$D$2:$D$101,_xlfn.AGGREGATE(15,6,(ROW(Data!$B$2:$B$101)-ROW(Data!$B$2)+1)/(Data!$B$2:$B$101=B$9),ROWS(B$10:B35))),"") -> 19.5 | J35: =IF(AND(ISNUMBER(A12),OR(A12<$J$4,A12>$K$4)),A12,NA()) -> #N/A | K35: 1 | L35: =IF(AND(ISNUMBER(B12),OR(B12<$J$5,B12>$K$5)),B12,NA()) -> #N/A | M35: 2
A36: =IFERROR(INDEX(Data!$D$2:$D$101,_xlfn.AGGREGATE(15,6,(ROW(Data!$B$2:$B$101)-ROW(Data!$B$2)+1)/(Data!$B$2:$B$101=A$9),ROWS(A$10:A36))),"") -> 107 | B36: =IFERROR(INDEX(Data!$D$2:$D$101,_xlfn.AGGREGATE(15,6,(ROW(Data!$B$2:$B$101)-ROW(Data!$B$2)+1)/(Data!$B$2:$B$101=B$9),ROWS(B$10:B36))),"") -> 62.4 | J36: =IF(AND(ISNUMBER(A13),OR(A13<$J$4,A13>$K$4)),A13,NA()) -> #N/A | K36: 1 | L36: =IF(AND(ISNUMBER(B13),OR(B13<$J$5,B13>$K$5)),B13,NA()) -> #N/A | M36: 2
A37: =IFERROR(INDEX(Data!$D$2:$D$101,_xlfn.AGGREGATE(15,6,(ROW(Data!$B$2:$B$101)-ROW(Data!$B$2)+1)/(Data!$B$2:$B$101=A$9),ROWS(A$10:A37))),"") -> 159.75 | B37: =IFERROR(INDEX(Data!$D$2:$D$101,_xlfn.AGGREGATE(15,6,(ROW(Data!$B$2:$B$101)-ROW(Data!$B$2)+1)/(Data!$B$2:$B$101=B$9),ROWS(B$10:B37))),"") -> 23.8 | J37: =IF(AND(ISNUMBER(A14),OR(A14<$J$4,A14>$K$4)),A14,NA()) -> #N/A | K37: 1 | L37: =IF(AND(ISNUMBER(B14),OR(B14<$J$5,B14>$K$5)),B14,NA()) -> #N/A | M37: 2
A38: =IFERROR(INDEX(Data!$D$2:$D$101,_xlfn.AGGREGATE(15,6,(ROW(Data!$B$2:$B$101)-ROW(Data!$B$2)+1)/(Data!$B$2:$B$101=A$9),ROWS(A$10:A38))),"") -> 66 | B38: =IFERROR(INDEX(Data!$D$2:$D$101,_xlfn.AGGREGATE(15,6,(ROW(Data!$B$2:$B$101)-ROW(Data!$B$2)+1)/(Data!$B$2:$B$101=B$9),ROWS(B$10:B38))),"") -> 39.6 | J38: =IF(AND(ISNUMBER(A15),OR(A15<$J$4,A15>$K$4)),A15,NA()) -> #N/A | K38: 1 | L38: =IF(AND(ISNUMBER(B15),OR(B15<$J$5,B15>$K$5)),B15,NA()) -> #N/A | M38: 2
A39: =IFERROR(INDEX(Data!$D$2:$D$101,_xlfn.AGGREGATE(15,6,(ROW(Data!$B$2:$B$101)-ROW(Data!$B$2)+1)/(Data!$B$2:$B$101=A$9),ROWS(A$10:A39))),"") -> 39.5 | B39: =IFERROR(INDEX(Data!$D$2:$D$101,_xlfn.AGGREGATE(15,6,(ROW(Data!$B$2:$B$101)-ROW(Data!$B$2)+1)/(Data!$B$2:$B$101=B$9),ROWS(B$10:B39))),"") -> 63.64 | J39: =IF(AND(ISNUMBER(A16),OR(A16<$J$4,A16>$K$4)),A16,NA()) -> #N/A | K39: 1 | L39: =IF(AND(ISNUMBER(B16),OR(B16<$J$5,B16>$K$5)),B16,NA()) -> #N/A | M39: 2
A40: =IFERROR(INDEX(Data!$D$2:$D$101,_xlfn.AGGREGATE(15,6,(ROW(Data!$B$2:$B$101)-ROW(Data!$B$2)+1)/(Data!$B$2:$B$101=A$9),ROWS(A$10:A40))),"") | B40: =IFERROR(INDEX(Data!$D$2:$D$101,_xlfn.AGGREGATE(15,6,(ROW(Data!$B$2:$B$101)-ROW(Data!$B$2)+1)/(Data!$B$2:$B$101=B$9),ROWS(B$10:B40))),"") -> 14.82 | J40: =IF(AND(ISNUMBER(A17),OR(A17<$J$4,A17>$K$4)),A17,NA()) -> #N/A | K40: 1 | L40: =IF(AND(ISNUMBER(B17),OR(B17<$J$5,B17>$K$5)),B17,NA()) -> #N/A | M40: 2
A41: =IFERROR(INDEX(Data!$D$2:$D$101,_xlfn.AGGREGATE(15,6,(ROW(Data!$B$2:$B$101)-ROW(Data!$B$2)+1)/(Data!$B$2:$B$101=A$9),ROWS(A$10:A41))),"") | B41: =IFERROR(INDEX(Data!$D$2:$D$101,_xlfn.AGGREGATE(15,6,(ROW(Data!$B$2:$B$101)-ROW(Data!$B$2)+1)/(Data!$B$2:$B$101=B$9),ROWS(B$10:B41))),"") -> 145.2 | J41: =IF(AND(ISNUMBER(A18),OR(A18<$J$4,A18>$K$4)),A18,NA()) -> #N/A | K41: 1 | L41: =IF(AND(ISNUMBER(B18),OR(B18<$J$5,B18>$K$5)),B18,NA()) -> #N/A | M41: 2
A42: =IFERROR(INDEX(Data!$D$2:$D$101,_xlfn.AGGREGATE(15,6,(ROW(Data!$B$2:$B$101)-ROW(Data!$B$2)+1)/(Data!$B$2:$B$101=A$9),ROWS(A$10:A42))),"") | B42: =IFERROR(INDEX(Data!$D$2:$D$101,_xlfn.AGGREGATE(15,6,(ROW(Data!$B$2:$B$101)-ROW(Data!$B$2)+1)/(Data!$B$2:$B$101=B$9),ROWS(B$10:B42))),"") -> 176.62 | J42: =IF(AND(ISNUMBER(A19),OR(A19<$J$4,A19>$K$4)),A19,NA()) -> #N/A | K42: 1 | L42: =IF(AND(ISNUMBER(B19),OR(B19<$J$5,B19>$K$5)),B19,NA()) -> #N/A | M42: 2
A43: =IFERROR(INDEX(Data!$D$2:$D$101,_xlfn.AGGREGATE(15,6,(ROW(Data!$B$2:$B$101)-ROW(Data!$B$2)+1)/(Data!$B$2:$B$101=A$9),ROWS(A$10:A43))),"") | B43: =IFERROR(INDEX(Data!$D$2:$D$101,_xlfn.AGGREGATE(15,6,(ROW(Data!$B$2:$B$101)-ROW(Data!$B$2)+1)/(Data!$B$2:$B$101=B$9),ROWS(B$10:B43))),"") -> 118.8 | J43: =IF(AND(ISNUMBER(A20),OR(A20<$J$4,A20>$K$4)),A20,NA()) -> #N/A | K43: 1 | L43: =IF(AND(ISNUMBER(B20),OR(B20<$J$5,B20>$K$5)),B20,NA()) -> #N/A | M43: 2
A44: =IFERROR(INDEX(Data!$D$2:$D$101,_xlfn.AGGREGATE(15,6,(ROW(Data!$B$2:$B$101)-ROW(Data!$B$2)+1)/(Data!$B$2:$B$101=A$9),ROWS(A$10:A44))),"") | B44: =IFERROR(INDEX(Data!$D$2:$D$101,_xlfn.AGGREGATE(15,6,(ROW(Data!$B$2:$B$101)-ROW(Data!$B$2)+1)/(Data!$B$2:$B$101=B$9),ROWS(B$10:B44))),"") -> 141.6 | J44: =IF(AND(ISNUMBER(A21),OR(A21<$J$4,A21>$K$4)),A21,NA()) -> #N/A | K44: 1 | L44: =IF(AND(ISNUMBER(B21),OR(B21<$J$5,B21>$K$5)),B21,NA()) -> #N/A | M44: 2
...

Sheet 07 Association
A1: Week 3: Items and Net Sales
A3: Sample covariance | B3: =_xlfn.COVARIANCE.S(Data!$C$2:$C$101,Data!$D$2:$D$101) -> 115.0009
A4: Correlation | B4: =CORREL(Data!$C$2:$C$101,Data!$D$2:$D$101) -> 0.75505939
A5: Trendline slope | B5: =SLOPE(Data!$D$2:$D$101,Data!$C$2:$C$101) -> 15.361176
A6: Trendline intercept | B6: =INTERCEPT(Data!$D$2:$D$101,Data!$C$2:$C$101) -> 28.137514
A9: Items | B9: Net Sales ($)
A10: =Data!C2 -> 1 | B10: =Data!D2 -> 39.5
A11: =Data!C3 -> 1 | B11: =Data!D3 -> 102.4
A12: =Data!C4 -> 1 | B12: =Data!D4 -> 22.5
A13: =Data!C5 -> 5 | B13: =Data!D5 -> 100.4
A14: =Data!C6 -> 2 | B14: =Data!D6 -> 54
A15: =Data!C7 -> 1 | B15: =Data!D7 -> 44.5
A16: =Data!C8 -> 2 | B16: =Data!D8 -> 78
A17: =Data!C9 -> 1 | B17: =Data!D9 -> 22.5
A18: =Data!C10 -> 2 | B18: =Data!D10 -> 56.52
A19: =Data!C11 -> 1 | B19: =Data!D11 -> 44.5
A20: =Data!C12 -> 1 | B20: =Data!D12 -> 29.5
A21: =Data!C13 -> 1 | B21: =Data!D13 -> 31.6
... A109: =Data!C101 -> 1 | B109: =Data!D101 -> 28.44
A112: How to recreate this output in Excel
A113: 1. Use Items in Data!C2:C101 and Net Sales in Data!D2:D101.
A114: 2. Calculate sample covariance with =COVARIANCE.S(Data!C2:C101,Data!D2:D101).
A115: 3. Calculate correlation with =CORREL(Data!C2:C101,Data!D2:D101).
A116: 4. Select both variables, then choose Insert, Scatter, Scatter with only markers.
A117: 5. Right-click a marker, add a linear trendline, and display the equation and R-squared value.
A118: 6. Use =SLOPE(Data!D2:D101,Data!C2:C101) and =INTERCEPT(Data!D2:D101,Data!C2:C101) to reproduce the fitted line numerically.
